2023-05-29 12:58:04,249 INFO: Microblog startup [in /Users/craigolson/Documents/Development/microblog/app/__init__.py:43]
2023-05-29 12:58:16,004 ERROR: Exception on /edit_profile [POST] [in /Users/craigolson/Documents/Development/microblog/venv/lib/python3.10/site-packages/flask/app.py:1414]
Traceback (most recent call last):
  File "/Users/craigolson/Documents/Development/microblog/venv/lib/python3.10/site-packages/sqlalchemy/engine/base.py", line 1968, in _exec_single_context
    self.dialect.do_execute(
  File "/Users/craigolson/Documents/Development/microblog/venv/lib/python3.10/site-packages/sqlalchemy/engine/default.py", line 920, in do_execute
    cursor.execute(statement, parameters)
sqlite3.InterfaceError: Error binding parameter 0 - probably unsupported type.

The above exception was the direct cause of the following exception:

Traceback (most recent call last):
  File "/Users/craigolson/Documents/Development/microblog/venv/lib/python3.10/site-packages/flask/app.py", line 2190, in wsgi_app
    response = self.full_dispatch_request()
  File "/Users/craigolson/Documents/Development/microblog/venv/lib/python3.10/site-packages/flask/app.py", line 1486, in full_dispatch_request
    rv = self.handle_user_exception(e)
  File "/Users/craigolson/Documents/Development/microblog/venv/lib/python3.10/site-packages/flask/app.py", line 1484, in full_dispatch_request
    rv = self.dispatch_request()
  File "/Users/craigolson/Documents/Development/microblog/venv/lib/python3.10/site-packages/flask/app.py", line 1469, in dispatch_request
    return self.ensure_sync(self.view_functions[rule.endpoint])(**view_args)
  File "/Users/craigolson/Documents/Development/microblog/venv/lib/python3.10/site-packages/flask_login/utils.py", line 290, in decorated_view
    return current_app.ensure_sync(func)(*args, **kwargs)
  File "/Users/craigolson/Documents/Development/microblog/app/routes.py", line 81, in edit_profile
    if form.validate_on_submit():
  File "/Users/craigolson/Documents/Development/microblog/venv/lib/python3.10/site-packages/flask_wtf/form.py", line 86, in validate_on_submit
    return self.is_submitted() and self.validate(extra_validators=extra_validators)
  File "/Users/craigolson/Documents/Development/microblog/venv/lib/python3.10/site-packages/wtforms/form.py", line 329, in validate
    return super().validate(extra)
  File "/Users/craigolson/Documents/Development/microblog/venv/lib/python3.10/site-packages/wtforms/form.py", line 146, in validate
    if not field.validate(self, extra):
  File "/Users/craigolson/Documents/Development/microblog/venv/lib/python3.10/site-packages/wtforms/fields/core.py", line 242, in validate
    stop_validation = self._run_validation_chain(form, chain)
  File "/Users/craigolson/Documents/Development/microblog/venv/lib/python3.10/site-packages/wtforms/fields/core.py", line 262, in _run_validation_chain
    validator(form, self)
  File "/Users/craigolson/Documents/Development/microblog/app/forms.py", line 40, in validate_username
    user = User.query.filter_by(username=self.username).first()
  File "/Users/craigolson/Documents/Development/microblog/venv/lib/python3.10/site-packages/sqlalchemy/orm/query.py", line 2747, in first
    return self.limit(1)._iter().first()  # type: ignore
  File "/Users/craigolson/Documents/Development/microblog/venv/lib/python3.10/site-packages/sqlalchemy/orm/query.py", line 2846, in _iter
    result: Union[ScalarResult[_T], Result[_T]] = self.session.execute(
  File "/Users/craigolson/Documents/Development/microblog/venv/lib/python3.10/site-packages/sqlalchemy/orm/session.py", line 2232, in execute
    return self._execute_internal(
  File "/Users/craigolson/Documents/Development/microblog/venv/lib/python3.10/site-packages/sqlalchemy/orm/session.py", line 2127, in _execute_internal
    result: Result[Any] = compile_state_cls.orm_execute_statement(
  File "/Users/craigolson/Documents/Development/microblog/venv/lib/python3.10/site-packages/sqlalchemy/orm/context.py", line 293, in orm_execute_statement
    result = conn.execute(
  File "/Users/craigolson/Documents/Development/microblog/venv/lib/python3.10/site-packages/sqlalchemy/engine/base.py", line 1413, in execute
    return meth(
  File "/Users/craigolson/Documents/Development/microblog/venv/lib/python3.10/site-packages/sqlalchemy/sql/elements.py", line 483, in _execute_on_connection
    return connection._execute_clauseelement(
  File "/Users/craigolson/Documents/Development/microblog/venv/lib/python3.10/site-packages/sqlalchemy/engine/base.py", line 1637, in _execute_clauseelement
    ret = self._execute_context(
  File "/Users/craigolson/Documents/Development/microblog/venv/lib/python3.10/site-packages/sqlalchemy/engine/base.py", line 1846, in _execute_context
    return self._exec_single_context(
  File "/Users/craigolson/Documents/Development/microblog/venv/lib/python3.10/site-packages/sqlalchemy/engine/base.py", line 1987, in _exec_single_context
    self._handle_dbapi_exception(
  File "/Users/craigolson/Documents/Development/microblog/venv/lib/python3.10/site-packages/sqlalchemy/engine/base.py", line 2344, in _handle_dbapi_exception
    raise sqlalchemy_exception.with_traceback(exc_info[2]) from e
  File "/Users/craigolson/Documents/Development/microblog/venv/lib/python3.10/site-packages/sqlalchemy/engine/base.py", line 1968, in _exec_single_context
    self.dialect.do_execute(
  File "/Users/craigolson/Documents/Development/microblog/venv/lib/python3.10/site-packages/sqlalchemy/engine/default.py", line 920, in do_execute
    cursor.execute(statement, parameters)
sqlalchemy.exc.InterfaceError: (sqlite3.InterfaceError) Error binding parameter 0 - probably unsupported type.
[SQL: SELECT user.id AS user_id, user.username AS user_username, user.email AS user_email, user.password_hash AS user_password_hash, user.about_me AS user_about_me, user.last_seen AS user_last_seen 
FROM user 
WHERE user.username = ?
 LIMIT ? OFFSET ?]
[parameters: (<wtforms.fields.simple.StringField object at 0x105b55de0>, 1, 0)]
(Background on this error at: https://sqlalche.me/e/20/rvf5)
2023-05-29 12:58:31,635 INFO: Microblog startup [in /Users/craigolson/Documents/Development/microblog/app/__init__.py:43]
